Workbook

Sheet Ratios
A1: Company | B1: Years | C1: EBITDA Margin | D1: Free Cashflow | E1: Net Debt | F1: ROE | G1: Revenue Growth
A2: Sun Pharmaceutical | B2: 2022 | C2: =(('Sun Pharmaceutical '!B13+'Sun Pharmaceutical '!B19)/'Sun Pharmaceutical '!B4)*100 -> 32.084648 | D2: ='Sun Pharmaceutical '!B100 -> 7550 | E2: ='Sun Pharmaceutical '!B37-'Sun Pharmaceutical '!B64 -> -3743 | F2: =('Sun Pharmaceutical '!B22/('Sun Pharmaceutical '!B35+'Sun Pharmaceutical '!B36))*100 -> 7.058799 | G2: ='Sun Pharmaceutical '!B5 -> 0.1539
A3: Sun Pharmaceutical | B3: 2023 | C3: =(('Sun Pharmaceutical '!C13+'Sun Pharmaceutical '!C19)/'Sun Pharmaceutical '!C4)*100 -> 32.308709 | D3: ='Sun Pharmaceutical '!C100 -> 2895 | E3: ='Sun Pharmaceutical '!C37-'Sun Pharmaceutical '!C64 -> 1116 | F3: =('Sun Pharmaceutical '!C22/('Sun Pharmaceutical '!C35+'Sun Pharmaceutical '!C36))*100 -> 15.203143 | G3: ='Sun Pharmaceutical '!C5 -> 0.1353
A4: Sun Pharmaceutical | B4: 2024 | C4: =(('Sun Pharmaceutical '!D13+'Sun Pharmaceutical '!D19)/'Sun Pharmaceutical '!D4)*100 -> 32.115389 | D4: ='Sun Pharmaceutical '!D100 -> 9964 | E4: ='Sun Pharmaceutical '!D37-'Sun Pharmaceutical '!D64 -> -7247 | F4: =('Sun Pharmaceutical '!D22/('Sun Pharmaceutical '!D35+'Sun Pharmaceutical '!D36))*100 -> 15.094162 | G4: ='Sun Pharmaceutical '!D5 -> 0.1051
A5: Sun Pharmaceutical | B5: 2025 | C5: =(('Sun Pharmaceutical '!E13+'Sun Pharmaceutical '!E19)/'Sun Pharmaceutical '!E4)*100 -> 33.643349 | D5: ='Sun Pharmaceutical '!E100 -> 12005 | E5: ='Sun Pharmaceutical '!E37-'Sun Pharmaceutical '!E64 -> -8970 | F5: =('Sun Pharmaceutical '!E22/('Sun Pharmaceutical '!E35+'Sun Pharmaceutical '!E36))*100 -> 15.183195 | G5: ='Sun Pharmaceutical '!E5 -> 0.0842
A6: Sun Pharmaceutical | B6: 2026 | C6: =(('Sun Pharmaceutical '!F13+'Sun Pharmaceutical '!F19)/'Sun Pharmaceutical '!F4)*100 -> 33.250659 | D6: ='Sun Pharmaceutical '!F100 -> 8906 | E6: ='Sun Pharmaceutical '!F37-'Sun Pharmaceutical '!F64 -> -6976 | F6: =('Sun Pharmaceutical '!F22/('Sun Pharmaceutical '!F35+'Sun Pharmaceutical '!F36))*100 -> 13.771688 | G6: ='Sun Pharmaceutical '!F5 -> 0.1119
A7: Dr Reddy | B7: 2022 | C7: =(('Dr Reddy'!B11+'Dr Reddy'!B17)/'Dr Reddy'!B4)*100 -> 22.896264 | D7: ='Dr Reddy'!B96 -> 1238 | E7: ='Dr Reddy'!B35-'Dr Reddy'!B62 -> 965 | F7: =('Dr Reddy'!B20/('Dr Reddy'!B33+'Dr Reddy'!B34))*100 -> 11.357485 | G7: ='Dr Reddy'!B5 -> 0.1311
A8: Dr Reddy | B8: 2023 | C8: =(('Dr Reddy'!C11+'Dr Reddy'!C17)/'Dr Reddy'!C4)*100 -> 31.293069 | D8: ='Dr Reddy'!C96 -> 4009 | E8: ='Dr Reddy'!C35-'Dr Reddy'!C62 -> -383 | F8: =('Dr Reddy'!C20/('Dr Reddy'!C33+'Dr Reddy'!C34))*100 -> 19.354977 | G8: ='Dr Reddy'!C5 -> 0.145
A9: Dr Reddy | B9: 2024 | C9: =(('Dr Reddy'!D11+'Dr Reddy'!D17)/'Dr Reddy'!D4)*100 -> 33.568955 | D9: ='Dr Reddy'!D96 -> 1908 | E9: ='Dr Reddy'!D35-'Dr Reddy'!D62 -> 274 | F9: =('Dr Reddy'!D20/('Dr Reddy'!D33+'Dr Reddy'!D34))*100 -> 19.742337 | G9: ='Dr Reddy'!D5 -> 0.1354
A10: Dr Reddy | B10: 2025 | C10: =(('Dr Reddy'!E11+'Dr Reddy'!E17)/'Dr Reddy'!E4)*100 -> 31.402402 | D10: ='Dr Reddy'!E96 -> 1327 | E10: ='Dr Reddy'!E35-'Dr Reddy'!E62 -> 2217 | F10: =('Dr Reddy'!E20/('Dr Reddy'!E33+'Dr Reddy'!E34))*100 -> 17.064592 | G10: ='Dr Reddy'!E5 -> 0.1654
A11: Dr Reddy | B11: 2026 | C11: =(('Dr Reddy'!F11+'Dr Reddy'!F17)/'Dr Reddy'!F4)*100 -> 25.261128 | D11: ='Dr Reddy'!F96 -> 2004 | E11: ='Dr Reddy'!F35-'Dr Reddy'!F62 -> 4385 | F11: =('Dr Reddy'!F20/('Dr Reddy'!F33+'Dr Reddy'!F34))*100 -> 10.973293 | G11: ='Dr Reddy'!F5 -> 0.0324
A12: Divi's Laboratories | B12: 2022 | C12: =(('Divis Laboratories'!B11+'Divis Laboratories'!B17)/'Divis Laboratories'!B4)*100 -> 46.841518 | D12: ='Divis Laboratories'!B91 -> 1199 | E12: ='Divis Laboratories'!B33-'Divis Laboratories'!B59 -> -2815 | F12: =('Divis Laboratories'!B20/('Divis Laboratories'!B31+'Divis Laboratories'!B32))*100 -> 25.238745 | G12: ='Divis Laboratories'!B5 -> 0.2856
A13: Divi's Laboratories | B13: 2023 | C13: =(('Divis Laboratories'!C11+'Divis Laboratories'!C17)/'Divis Laboratories'!C4)*100 -> 34.925335 | D13: ='Divis Laboratories'!C91 -> 1987 | E13: ='Divis Laboratories'!C33-'Divis Laboratories'!C59 -> -4210 | F13: =('Divis Laboratories'!C20/('Divis Laboratories'!C31+'Divis Laboratories'!C32))*100 -> 14.279001 | G13: ='Divis Laboratories'!C5 -> -0.1331
A14: Divi's Laboratories | B14: 2024 | C14: =(('Divis Laboratories'!D11+'Divis Laboratories'!D17)/'Divis Laboratories'!D4)*100 -> 32.989165 | D14: ='Divis Laboratories'!D91 -> 258 | E14: ='Divis Laboratories'!D33-'Divis Laboratories'!D59 -> -3977 | F14: =('Divis Laboratories'!D20/('Divis Laboratories'!D31+'Divis Laboratories'!D32))*100 -> 11.789846 | G14: ='Divis Laboratories'!D5 -> 0.01
A15: Divi's Laboratories | B15: 2025 | C15: =(('Divis Laboratories'!E11+'Divis Laboratories'!E17)/'Divis Laboratories'!E4)*100 -> 36.057692 | D15: ='Divis Laboratories'!E91 -> 215 | E15: ='Divis Laboratories'!E33-'Divis Laboratories'!E59 -> -3711 | F15: =('Divis Laboratories'!E20/('Divis Laboratories'!E31+'Divis Laboratories'!E32))*100 -> 14.636916 | G15: ='Divis Laboratories'!E5 -> 0.1931
A16: Divi's Laboratories | B16: 2026 | C16: =(('Divis Laboratories'!F11+'Divis Laboratories'!F17)/'Divis Laboratories'!F4)*100 -> 36.979167 | D16: ='Divis Laboratories'!F91 -> 221 | E16: ='Divis Laboratories'!F33-'Divis Laboratories'!F59 -> -3407 | F16: =('Divis Laboratories'!F20/('Divis Laboratories'!F31+'Divis Laboratories'!F32))*100 -> 15.321282 | G16: ='Divis Laboratories'!F5 -> 0.1282
A17: Cipla | B17: 2022 | C17: =((Cipla!B11+Cipla!B17)/Cipla!B4)*100 -> 25.754721 | D17: =Cipla!B100 -> 2645 | E17: =Cipla!B35-Cipla!B63 -> -872 | F17: =(Cipla!B20/(Cipla!B33+Cipla!B34))*100 -> 12.221103 | G17: =Cipla!B5 -> 0.1359
A18: Cipla | B18: 2023 | C18: =((Cipla!C11+Cipla!C17)/Cipla!C4)*100 -> 27.244759 | D18: =Cipla!C100 -> 2102 | E18: =Cipla!C35-Cipla!C63 -> -762 | F18: =(Cipla!C20/(Cipla!C33+Cipla!C34))*100 -> 12.103217 | G18: =Cipla!C5 -> 0.0455
A19: Cipla | B19: 2024 | C19: =((Cipla!D11+Cipla!D17)/Cipla!D4)*100 -> 28.486071 | D19: =Cipla!D100 -> 2819 | E19: =Cipla!D35-Cipla!D63 -> -316 | F19: =(Cipla!D20/(Cipla!D33+Cipla!D34))*100 -> 15.554557 | G19: =Cipla!D5 -> 0.1328
A20: Cipla | B20: 2025 | C20: =((Cipla!E11+Cipla!E17)/Cipla!E4)*100 -> 29.893277 | D20: =Cipla!E100 -> 3490 | E20: =Cipla!E35-Cipla!E63 -> -362 | F20: =(Cipla!E20/(Cipla!E33+Cipla!E34))*100 -> 16.891069 | G20: =Cipla!E5 -> 0.0688
A21: Cipla | B21: 2026 | C21: =((Cipla!F11+Cipla!F17)/Cipla!F4)*100 -> 25.189078 | D21: =Cipla!F100 -> 928 | E21: =Cipla!F35-Cipla!F63 -> -693 | F21: =(Cipla!F20/(Cipla!F33+Cipla!F34))*100 -> 11.21631 | G21: =Cipla!F5 -> 0.0223
A22: Torrent Pharma | B22: 2022 | C22: =(('Torrent Pharma'!B12+'Torrent Pharma'!B18)/'Torrent Pharma'!B3)*100 -> 36.35402 | D22: ='Torrent Pharma'!B96 -> 1607 | E22: ='Torrent Pharma'!E35-'Torrent Pharma'!B63 -> 2799 | F22: ='Torrent Pharma'!B21/('Torrent Pharma'!B33+'Torrent Pharma'!B34)*100 -> 13.052243 | G22: ='Torrent Pharma'!B4 -> 0.0629
A23: Torrent Pharma | B23: 2023 | C23: =(('Torrent Pharma'!C12+'Torrent Pharma'!C18)/'Torrent Pharma'!C3)*100 -> 36.891892 | D23: ='Torrent Pharma'!C96 -> 1953 | E23: ='Torrent Pharma'!F35-'Torrent Pharma'!C63 -> 14455 | F23: ='Torrent Pharma'!C21/('Torrent Pharma'!C33+'Torrent Pharma'!C34)*100 -> 20.087125 | G23: ='Torrent Pharma'!C4 -> 0.1307
A24: Torrent Pharma | B24: 2024 | C24: =(('Torrent Pharma'!D12+'Torrent Pharma'!D18)/'Torrent Pharma'!D3)*100 -> 38.926174 | D24: ='Torrent Pharma'!D96 -> 2967 | E24: ='Torrent Pharma'!G35-'Torrent Pharma'!D63 -> -839 | F24: ='Torrent Pharma'!D21/('Torrent Pharma'!D33+'Torrent Pharma'!D34)*100 -> 24.154026 | G24: ='Torrent Pharma'!D4 -> 0.1151
A25: Torrent Pharma | B25: 2025 | C25: =(('Torrent Pharma'!E12+'Torrent Pharma'!E18)/'Torrent Pharma'!E3)*100 -> 39.215005 | D25: ='Torrent Pharma'!E96 -> 1991 | E25: ='Torrent Pharma'!H35-'Torrent Pharma'!E63 -> -579 | F25: ='Torrent Pharma'!E21/('Torrent Pharma'!E33+'Torrent Pharma'!E34)*100 -> 25.177866 | G25: ='Torrent Pharma'!E4 -> 0.0735
A26: Torrent Pharma | B26: 2026 | C26: =(('Torrent Pharma'!F12+'Torrent Pharma'!F18)/'Torrent Pharma'!F3)*100 -> 40.608011 | D26: ='Torrent Pharma'!F96 -> 2386 | E26: ='Torrent Pharma'!I35-'Torrent Pharma'!F63 -> -1165 | F26: ='Torrent Pharma'!F21/('Torrent Pharma'!F33+'Torrent Pharma'!F34)*100 -> 25.488794 | G26: ='Torrent Pharma'!F4 -> 0.2139
A27: Zydus Lifesciences Ltd | B27: 2022 | C27: =(('Zydus Lifesciences Ltd'!B19+'Zydus Lifesciences Ltd'!B16)/'Zydus Lifesciences Ltd'!B3)*100 -> 34.923027 | D27: ='Zydus Lifesciences Ltd'!B98 -> 1050 | E27: ='Zydus Lifesciences Ltd'!B34-'Zydus Lifesciences Ltd'!B61 -> 3114 | F27: ='Zydus Lifesciences Ltd'!B19/('Zydus Lifesciences Ltd'!B32+'Zydus Lifesciences Ltd'!B33)*100 -> 27.166304 | G27: ='Zydus Lifesciences Ltd'!B4 -> 0.0108
A28: Zydus Lifesciences Ltd | B28: 2023 | C28: =(('Zydus Lifesciences Ltd'!C19+'Zydus Lifesciences Ltd'!C16)/'Zydus Lifesciences Ltd'!C3)*100 -> 16.331148 | D28: ='Zydus Lifesciences Ltd'!C98 -> 1697 | E28: ='Zydus Lifesciences Ltd'!C34-'Zydus Lifesciences Ltd'!C61 -> 622 | F28: ='Zydus Lifesciences Ltd'!C19/('Zydus Lifesciences Ltd'!C32+'Zydus Lifesciences Ltd'!C33)*100 -> 11.943366 | G28: ='Zydus Lifesciences Ltd'!C4 -> 0.1292
A29: Zydus Lifesciences Ltd | B29: 2024 | C29: =(('Zydus Lifesciences Ltd'!D19+'Zydus Lifesciences Ltd'!D16)/'Zydus Lifesciences Ltd'!D3)*100 -> 24.233898 | D29: ='Zydus Lifesciences Ltd'!D98 -> 2345 | E29: ='Zydus Lifesciences Ltd'!D34-'Zydus Lifesciences Ltd'!D61 -> -301 | F29: ='Zydus Lifesciences Ltd'!D19/('Zydus Lifesciences Ltd'!D32+'Zydus Lifesciences Ltd'!D33)*100 -> 20.0353 | G29: ='Zydus Lifesciences Ltd'!D4 -> 0.134
A30: Zydus Lifesciences Ltd | B30: 2025 | C30: =(('Zydus Lifesciences Ltd'!E19+'Zydus Lifesciences Ltd'!E16)/'Zydus Lifesciences Ltd'!E3)*100 -> 24.046984 | D30: ='Zydus Lifesciences Ltd'!E98 -> 5139 | E30: ='Zydus Lifesciences Ltd'!E34-'Zydus Lifesciences Ltd'!E61 -> 256 | F30: ='Zydus Lifesciences Ltd'!E19/('Zydus Lifesciences Ltd'!E32+'Zydus Lifesciences Ltd'!E33)*100 -> 19.509039 | G30: ='Zydus Lifesciences Ltd'!E4 -> 0.189
A31: Zydus Lifesciences Ltd | B31: 2026 | C31: =(('Zydus Lifesciences Ltd'!F19+'Zydus Lifesciences Ltd'!F16)/'Zydus Lifesciences Ltd'!F3)*100 -> 24.060704 | D31: ='Zydus Lifesciences Ltd'!F98 -> -530 | E31: ='Zydus Lifesciences Ltd'!F34-'Zydus Lifesciences Ltd'!F61 -> 11079 | F31: ='Zydus Lifesciences Ltd'!F19/('Zydus Lifesciences Ltd'!F32+'Zydus Lifesciences Ltd'!F33)*100 -> 18.89938 | G31: ='Zydus Lifesciences Ltd'!F4 -> 0.1681
A32: Lupin | B32: 2022 | C32: =((Lupin!B19+Lupin!B16)/Lupin!B3)*100 -> 0.79853703 | D32: =Lupin!B96 -> -531 | E32: =Lupin!B34-Lupin!B61 -> 3060 | F32: =Lupin!B19/(Lupin!B32+Lupin!B33)*100 -> -12.573027 | G32: =Lupin!B4 -> 0.0819
A33: Lupin | B33: 2023 | C33: =((Lupin!C19+Lupin!C16)/Lupin!C3)*100 -> 7.985819 | D33: =Lupin!C96 -> 436 | E33: =Lupin!C34-Lupin!C61 -> 3249 | F33: =Lupin!C19/(Lupin!C32+Lupin!C33)*100 -> 3.5940634 | G33: =Lupin!C4 -> 0.0144
A34: Lupin | B34: 2024 | C34: =((Lupin!D19+Lupin!D16)/Lupin!D3)*100 -> 15.656389 | D34: =Lupin!D96 -> 2732 | E34: =Lupin!D34-Lupin!D61 -> 1719 | F34: =Lupin!D19/(Lupin!D32+Lupin!D33)*100 -> 13.547936 | G34: =Lupin!D4 -> 0.2025
A35: Lupin | B35: 2025 | C35: =((Lupin!E19+Lupin!E16)/Lupin!E3)*100 -> 19.706711 | D35: =Lupin!E96 -> 1347 | E35: =Lupin!E34-Lupin!E61 -> 2306 | F35: =Lupin!E19/(Lupin!E32+Lupin!E33)*100 -> 19.217578 | G35: =Lupin!E4 -> 0.1348
A36: Lupin | B36: 2026 | C36: =((Lupin!F19+Lupin!F16)/Lupin!F3)*100 -> 24.075399 | D36: =Lupin!F96 -> 5527 | E36: =Lupin!F34-Lupin!F61 -> 963 | F36: =Lupin!F19/(Lupin!F32+Lupin!F33)*100 -> 23.855132 | G36: =Lupin!F4 -> 0.2312
A37: Aurobindo Pharma Ltd | B37: 2022 | C37: =(('Aurobindo Pharma Ltd'!B19+'Aurobindo Pharma Ltd'!B16)/'Aurobindo Pharma Ltd'!B3)*100 -> 16.090386 | D37: ='Aurobindo Pharma Ltd'!B97 -> 2693 | E37: ='Aurobindo Pharma Ltd'!B33-'Aurobindo Pharma Ltd'!B61 -> -1339 | F37: ='Aurobindo Pharma Ltd'!B19/('Aurobindo Pharma Ltd'!B31+'Aurobindo Pharma Ltd'!B32)*100 -> 10.770671 | G37: ='Aurobindo Pharma Ltd'!B4 -> -0.0532
A38: Aurobindo Pharma Ltd | B38: 2023 | C38: =(('Aurobindo Pharma Ltd'!C19+'Aurobindo Pharma Ltd'!C16)/'Aurobindo Pharma Ltd'!C3)*100 -> 12.766043 | D38: ='Aurobindo Pharma Ltd'!C97 -> -323 | E38: ='Aurobindo Pharma Ltd'!C33-'Aurobindo Pharma Ltd'!C61 -> -798 | F38: ='Aurobindo Pharma Ltd'!C19/('Aurobindo Pharma Ltd'!C31+'Aurobindo Pharma Ltd'!C32)*100 -> 7.1833085 | G38: ='Aurobindo Pharma Ltd'!C4 -> 0.0597
A39: Aurobindo Pharma Ltd | B39: 2024 | C39: =(('Aurobindo Pharma Ltd'!D19+'Aurobindo Pharma Ltd'!D16)/'Aurobindo Pharma Ltd'!D3)*100 -> 16.174747 | D39: ='Aurobindo Pharma Ltd'!D97 -> -1067 | E39: ='Aurobindo Pharma Ltd'!D33-'Aurobindo Pharma Ltd'!D61 -> 370 | F39: ='Aurobindo Pharma Ltd'!D19/('Aurobindo Pharma Ltd'!D31+'Aurobindo Pharma Ltd'!D32)*100 -> 10.618906 | G39: ='Aurobindo Pharma Ltd'!D4 -> 0.1668
A40: Aurobindo Pharma Ltd | B40: 2025 | C40: =(('Aurobindo Pharma Ltd'!E19+'Aurobindo Pharma Ltd'!E16)/'Aurobindo Pharma Ltd'!E3)*100 -> 16.180179 | D40: ='Aurobindo Pharma Ltd'!E97 -> 1408 | E40: ='Aurobindo Pharma Ltd'!E33-'Aurobindo Pharma Ltd'!E61 -> 28 | F40: ='Aurobindo Pharma Ltd'!E19/('Aurobindo Pharma Ltd'!E31+'Aurobindo Pharma Ltd'!E32)*100 -> 10.66977 | G40: ='Aurobindo Pharma Ltd'!E4 -> 0.0939
...

Sheet Return
A1: Date | B1: ABBOTINDIA | C1: ALKEM | D1: AUROPHARMA | E1: LUPIN | F1: ZYDUSLIFE | G1: TORNTPHARM | H1: DRREDDY | I1: SUNPHARMA | J1: CIPLA | K1: DIVISLAB | L1: Portfolio Return | M1: SBI Net Asset Value | N1: Nippon Net Asset Value | O1: Return of SBI | P1: Return of Nippon | Q1: Portfolio 2 Return | R1: Portfolio 3 Return | S1: Portfolio 4 Return (SBI/Nippon Blend)
A2: 46080 | B2: 0.0066 | C2: -0.019558414 | D2: -0.00024576063 | E2: -0.01206 | F2: -0.017900906 | G2: -0.015114323 | H2: -0.025013265 | I2: -0.027272218 | J2: -0.0072895958 | K2: -0.010117393 | L2: =IFERROR(B2*'Stock Statistics'!$C$41+C2*'Stock Statistics'!$C$42+D2*'Stock Statistics'!$C$43+E2*'Stock Statistics'!$C$44+F2*'Stock Statistics'!$C$45+G2*'Stock Statistics'!$C$46+H2*'Stock Statistics'!$C$47+I2*'Stock Statistics'!$C$48+J2*'Stock Statistics'!$C$49+K2*'Stock Statistics'!$C$50,"") -> -0.012797188 | M2: 497.1341 | N2: 576.9248 | O2: =M2/M3-1 -> -0.010177489 | P2: =N2/N3-1 -> -0.0088691148 | Q2: =B2*'Portfolio 2 & 3'!$F$7+C2*'Portfolio 2 & 3'!$F$8+D2*'Portfolio 2 & 3'!$F$9+E2*'Portfolio 2 & 3'!$F$10+F2*'Portfolio 2 & 3'!$F$11+G2*'Portfolio 2 & 3'!$F$12+H2*'Portfolio 2 & 3'!$F$13+I2*'Portfolio 2 & 3'!$F$14+J2*'Portfolio 2 & 3'!$F$15+K2*'Portfolio 2 & 3'!$F$16 -> -0.013299705 | R2: =B2*'Portfolio 2 & 3'!$B$23+C2*'Portfolio 2 & 3'!$B$24+D2*'Portfolio 2 & 3'!$B$25+E2*'Portfolio 2 & 3'!$B$26+F2*'Portfolio 2 & 3'!$B$27+G2*'Portfolio 2 & 3'!$B$28+H2*'Portfolio 2 & 3'!$B$29+I2*'Portfolio 2 & 3'!$B$30+J2*'Portfolio 2 & 3'!$B$31+K2*'Portfolio 2 & 3'!$B$32 -> -0.015965014 | S2: =IFERROR(AVERAGE(O2,P2),"") -> -0.0095233018
A3: 46079 | B3: -0.0021 | C3: 0.022577778 | D3: 0.0075938919 | E3: 0.01352 | F3: 0.020496928 | G3: -0.0043223427 | H3: 0.009797168 | I3: 0.012186827 | J3: 0.0089146423 | K3: 0.012274255 | L3: =IFERROR(B3*'Stock Statistics'!$C$41+C3*'Stock Statistics'!$C$42+D3*'Stock Statistics'!$C$43+E3*'Stock Statistics'!$C$44+F3*'Stock Statistics'!$C$45+G3*'Stock Statistics'!$C$46+H3*'Stock Statistics'!$C$47+I3*'Stock Statistics'!$C$48+J3*'Stock Statistics'!$C$49+K3*'Stock Statistics'!$C$50,"") -> 0.010093915 | M3: 502.2457 | N3: 582.0874 | O3: =M3/M4-1 -> 0.011710969 | P3: =N3/N4-1 -> 0.0078702501 | Q3: =B3*'Portfolio 2 & 3'!$F$7+C3*'Portfolio 2 & 3'!$F$8+D3*'Portfolio 2 & 3'!$F$9+E3*'Portfolio 2 & 3'!$F$10+F3*'Portfolio 2 & 3'!$F$11+G3*'Portfolio 2 & 3'!$F$12+H3*'Portfolio 2 & 3'!$F$13+I3*'Portfolio 2 & 3'!$F$14+J3*'Portfolio 2 & 3'!$F$15+K3*'Portfolio 2 & 3'!$F$16 -> 0.010822137 | R3: =B3*'Portfolio 2 & 3'!$B$23+C3*'Portfolio 2 & 3'!$B$24+D3*'Portfolio 2 & 3'!$B$25+E3*'Portfolio 2 & 3'!$B$26+F3*'Portfolio 2 & 3'!$B$27+G3*'Portfolio 2 & 3'!$B$28+H3*'Portfolio 2 & 3'!$B$29+I3*'Portfolio 2 & 3'!$B$30+J3*'Portfolio 2 & 3'!$B$31+K3*'Portfolio 2 & 3'!$B$32 -> 0.01159166 | S3: =IFERROR(AVERAGE(O3,P3),"") -> 0.0097906098
A4: 46078 | B4: 0.0017 | C4: 0.023564735 | D4: 0.040450017 | E4: 0.01103 | F4: 0.017480777 | G4: 0.0047750063 | H4: 0.0048454084 | I4: 0.018708858 | J4: 0.014622748 | K4: 0.022380305 | L4: =IFERROR(B4*'Stock Statistics'!$C$41+C4*'Stock Statistics'!$C$42+D4*'Stock Statistics'!$C$43+E4*'Stock Statistics'!$C$44+F4*'Stock Statistics'!$C$45+G4*'Stock Statistics'!$C$46+H4*'Stock Statistics'!$C$47+I4*'Stock Statistics'!$C$48+J4*'Stock Statistics'!$C$49+K4*'Stock Statistics'!$C$50,"") -> 0.015955785 | M4: 496.432 | N4: 577.542 | O4: =M4/M5-1 -> 0.014566179 | P4: =N4/N5-1 -> 0.013631875 | Q4: =B4*'Portfolio 2 & 3'!$F$7+C4*'Portfolio 2 & 3'!$F$8+D4*'Portfolio 2 & 3'!$F$9+E4*'Portfolio 2 & 3'!$F$10+F4*'Portfolio 2 & 3'!$F$11+G4*'Portfolio 2 & 3'!$F$12+H4*'Portfolio 2 & 3'!$F$13+I4*'Portfolio 2 & 3'!$F$14+J4*'Portfolio 2 & 3'!$F$15+K4*'Portfolio 2 & 3'!$F$16 -> 0.016925966 | R4: =B4*'Portfolio 2 & 3'!$B$23+C4*'Portfolio 2 & 3'!$B$24+D4*'Portfolio 2 & 3'!$B$25+E4*'Portfolio 2 & 3'!$B$26+F4*'Portfolio 2 & 3'!$B$27+G4*'Portfolio 2 & 3'!$B$28+H4*'Portfolio 2 & 3'!$B$29+I4*'Portfolio 2 & 3'!$B$30+J4*'Portfolio 2 & 3'!$B$31+K4*'Portfolio 2 & 3'!$B$32 -> 0.015724575 | S4: =IFERROR(AVERAGE(O4,P4),"") -> 0.014099027
A5: 46077 | B5: -0.004 | C5: 0.00091066387 | D5: 0.011993742 | E5: -0.00102 | F5: -0.0045156672 | G5: 0.020962949 | H5: -0.0055071134 | I5: -0.00028863361 | J5: 0.00015077271 | K5: -0.0060379757 | L5: =IFERROR(B5*'Stock Statistics'!$C$41+C5*'Stock Statistics'!$C$42+D5*'Stock Statistics'!$C$43+E5*'Stock Statistics'!$C$44+F5*'Stock Statistics'!$C$45+G5*'Stock Statistics'!$C$46+H5*'Stock Statistics'!$C$47+I5*'Stock Statistics'!$C$48+J5*'Stock Statistics'!$C$49+K5*'Stock Statistics'!$C$50,"") -> 0.0012648738 | M5: 489.3047 | N5: 569.7749 | O5: =M5/M6-1 -> 0.0027319213 | P5: =N5/N6-1 -> -0.0023754595 | Q5: =B5*'Portfolio 2 & 3'!$F$7+C5*'Portfolio 2 & 3'!$F$8+D5*'Portfolio 2 & 3'!$F$9+E5*'Portfolio 2 & 3'!$F$10+F5*'Portfolio 2 & 3'!$F$11+G5*'Portfolio 2 & 3'!$F$12+H5*'Portfolio 2 & 3'!$F$13+I5*'Portfolio 2 & 3'!$F$14+J5*'Portfolio 2 & 3'!$F$15+K5*'Portfolio 2 & 3'!$F$16 -> 0.00064536416 | R5: =B5*'Portfolio 2 & 3'!$B$23+C5*'Portfolio 2 & 3'!$B$24+D5*'Portfolio 2 & 3'!$B$25+E5*'Portfolio 2 & 3'!$B$26+F5*'Portfolio 2 & 3'!$B$27+G5*'Portfolio 2 & 3'!$B$28+H5*'Portfolio 2 & 3'!$B$29+I5*'Portfolio 2 & 3'!$B$30+J5*'Portfolio 2 & 3'!$B$31+K5*'Portfolio 2 & 3'!$B$32 -> 0.00055071234 | S5: =IFERROR(AVERAGE(O5,P5),"") -> 0.00017823088
A6: 46076 | B6: 0.0067 | C6: 0.018267804 | D6: -0.0070762858 | E6: 0.00964 | F6: 0.0079933389 | G6: 0.015536224 | H6: 0.02108716 | I6: 0.0045813036 | J6: -0.010886586 | K6: 0.0003973931 | L6: =IFERROR(B6*'Stock Statistics'!$C$41+C6*'Stock Statistics'!$C$42+D6*'Stock Statistics'!$C$43+E6*'Stock Statistics'!$C$44+F6*'Stock Statistics'!$C$45+G6*'Stock Statistics'!$C$46+H6*'Stock Statistics'!$C$47+I6*'Stock Statistics'!$C$48+J6*'Stock Statistics'!$C$49+K6*'Stock Statistics'!$C$50,"") -> 0.0066240352 | M6: 487.9716 | N6: 571.1316 | O6: =M6/M7-1 -> 0.006126388 | P6: =N6/N7-1 -> 0.0081770622 | Q6: =B6*'Portfolio 2 & 3'!$F$7+C6*'Portfolio 2 & 3'!$F$8+D6*'Portfolio 2 & 3'!$F$9+E6*'Portfolio 2 & 3'!$F$10+F6*'Portfolio 2 & 3'!$F$11+G6*'Portfolio 2 & 3'!$F$12+H6*'Portfolio 2 & 3'!$F$13+I6*'Portfolio 2 & 3'!$F$14+J6*'Portfolio 2 & 3'!$F$15+K6*'Portfolio 2 & 3'!$F$16 -> 0.005933812 | R6: =B6*'Portfolio 2 & 3'!$B$23+C6*'Portfolio 2 & 3'!$B$24+D6*'Portfolio 2 & 3'!$B$25+E6*'Portfolio 2 & 3'!$B$26+F6*'Portfolio 2 & 3'!$B$27+G6*'Portfolio 2 & 3'!$B$28+H6*'Portfolio 2 & 3'!$B$29+I6*'Portfolio 2 & 3'!$B$30+J6*'Portfolio 2 & 3'!$B$31+K6*'Portfolio 2 & 3'!$B$32 -> 0.0086659228 | S6: =IFERROR(AVERAGE(O6,P6),"") -> 0.0071517251
A7: 46073 | B7: -0.0038 | C7: 0.0027896597 | D7: -0.01075636 | E7: 0.00063 | F7: -0.0018284574 | G7: 0.0036201022 | H7: -0.0014817125 | I7: 0.0064199837 | J7: 0.0091805252 | K7: -0.0010321556 | L7: =IFERROR(B7*'Stock Statistics'!$C$41+C7*'Stock Statistics'!$C$42+D7*'Stock Statistics'!$C$43+E7*'Stock Statistics'!$C$44+F7*'Stock Statistics'!$C$45+G7*'Stock Statistics'!$C$46+H7*'Stock Statistics'!$C$47+I7*'Stock Statistics'!$C$48+J7*'Stock Statistics'!$C$49+K7*'Stock Statistics'!$C$50,"") -> 0.00037415853 | M7: 485.0003 | N7: 566.4993 | O7: =M7/M8-1 -> -0.0017318398 | P7: =N7/N8-1 -> -0.00026136183 | Q7: =B7*'Portfolio 2 & 3'!$F$7+C7*'Portfolio 2 & 3'!$F$8+D7*'Portfolio 2 & 3'!$F$9+E7*'Portfolio 2 & 3'!$F$10+F7*'Portfolio 2 & 3'!$F$11+G7*'Portfolio 2 & 3'!$F$12+H7*'Portfolio 2 & 3'!$F$13+I7*'Portfolio 2 & 3'!$F$14+J7*'Portfolio 2 & 3'!$F$15+K7*'Portfolio 2 & 3'!$F$16 -> 0.00019418118 | R7: =B7*'Portfolio 2 & 3'!$B$23+C7*'Portfolio 2 & 3'!$B$24+D7*'Portfolio 2 & 3'!$B$25+E7*'Portfolio 2 & 3'!$B$26+F7*'Portfolio 2 & 3'!$B$27+G7*'Portfolio 2 & 3'!$B$28+H7*'Portfolio 2 & 3'!$B$29+I7*'Portfolio 2 & 3'!$B$30+J7*'Portfolio 2 & 3'!$B$31+K7*'Portfolio 2 & 3'!$B$32 -> 0.0017615928 | S7: =IFERROR(AVERAGE(O7,P7),"") -> -0.00099660082
A8: 46072 | B8: -0.0025 | C8: -0.015922401 | D8: 0.010175923 | E8: -0.00237 | F8: -0.0084061315 | G8: 0.0037047592 | H8: 0.0015621339 | I8: -0.0063790304 | J8: -0.015483775 | K8: 0.0022280576 | L8: =IFERROR(B8*'Stock Statistics'!$C$41+C8*'Stock Statistics'!$C$42+D8*'Stock Statistics'!$C$43+E8*'Stock Statistics'!$C$44+F8*'Stock Statistics'!$C$45+G8*'Stock Statistics'!$C$46+H8*'Stock Statistics'!$C$47+I8*'Stock Statistics'!$C$48+J8*'Stock Statistics'!$C$49+K8*'Stock Statistics'!$C$50,"") -> -0.0033390465 | M8: 485.8417 | N8: 566.6474 | O8: =M8/M9-1 -> -0.0061605394 | P8: =N8/N9-1 -> -0.0053610522 | Q8: =B8*'Portfolio 2 & 3'!$F$7+C8*'Portfolio 2 & 3'!$F$8+D8*'Portfolio 2 & 3'!$F$9+E8*'Portfolio 2 & 3'!$F$10+F8*'Portfolio 2 & 3'!$F$11+G8*'Portfolio 2 & 3'!$F$12+H8*'Portfolio 2 & 3'!$F$13+I8*'Portfolio 2 & 3'!$F$14+J8*'Portfolio 2 & 3'!$F$15+K8*'Portfolio 2 & 3'!$F$16 -> -0.0035525103 | R8: =B8*'Portfolio 2 & 3'!$B$23+C8*'Portfolio 2 & 3'!$B$24+D8*'Portfolio 2 & 3'!$B$25+E8*'Portfolio 2 & 3'!$B$26+F8*'Portfolio 2 & 3'!$B$27+G8*'Portfolio 2 & 3'!$B$28+H8*'Portfolio 2 & 3'!$B$29+I8*'Portfolio 2 & 3'!$B$30+J8*'Portfolio 2 & 3'!$B$31+K8*'Portfolio 2 & 3'!$B$32 -> -0.0060508028 | S8: =IFERROR(AVERAGE(O8,P8),"") -> -0.0057607958
A9: 46071 | B9: -0.006 | C9: 0.0013745075 | D9: -0.022836437 | E9: -0.01255 | F9: 0.0037500689 | G9: -0.011177907 | H9: -0.0035024907 | I9: 0.004251354 | J9: 0.0043902076 | K9: 0.015515152 | L9: =IFERROR(B9*'Stock Statistics'!$C$41+C9*'Stock Statistics'!$C$42+D9*'Stock Statistics'!$C$43+E9*'Stock Statistics'!$C$44+F9*'Stock Statistics'!$C$45+G9*'Stock Statistics'!$C$46+H9*'Stock Statistics'!$C$47+I9*'Stock Statistics'!$C$48+J9*'Stock Statistics'!$C$49+K9*'Stock Statistics'!$C$50,"") -> -0.0026785545 | M9: 488.8533 | N9: 569.7016 | O9: =M9/M10-1 -> 0.0050751997 | P9: =N9/N10-1 -> 8.3559494e-05 | Q9: =B9*'Portfolio 2 & 3'!$F$7+C9*'Portfolio 2 & 3'!$F$8+D9*'Portfolio 2 & 3'!$F$9+E9*'Portfolio 2 & 3'!$F$10+F9*'Portfolio 2 & 3'!$F$11+G9*'Portfolio 2 & 3'!$F$12+H9*'Portfolio 2 & 3'!$F$13+I9*'Portfolio 2 & 3'!$F$14+J9*'Portfolio 2 & 3'!$F$15+K9*'Portfolio 2 & 3'!$F$16 -> -0.0027990656 | R9: =B9*'Portfolio 2 & 3'!$B$23+C9*'Portfolio 2 & 3'!$B$24+D9*'Portfolio 2 & 3'!$B$25+E9*'Portfolio 2 & 3'!$B$26+F9*'Portfolio 2 & 3'!$B$27+G9*'Portfolio 2 & 3'!$B$28+H9*'Portfolio 2 & 3'!$B$29+I9*'Portfolio 2 & 3'!$B$30+J9*'Portfolio 2 & 3'!$B$31+K9*'Portfolio 2 & 3'!$B$32 -> 0.0010160793 | S9: =IFERROR(AVERAGE(O9,P9),"") -> 0.0025793796
A10: 46070 | B10: 0.0126 | C10: -0.0043791625 | D10: 0.0017727503 | E10: 0.00559 | F10: -0.0041737602 | G10: -0.00072744339 | H10: 0.012131716 | I10: 0.0097618348 | J10: -0.0092155706 | K10: 0.0061793642 | L10: =IFERROR(B10*'Stock Statistics'!$C$41+C10*'Stock Statistics'!$C$42+D10*'Stock Statistics'!$C$43+E10*'Stock Statistics'!$C$44+F10*'Stock Statistics'!$C$45+G10*'Stock Statistics'!$C$46+H10*'Stock Statistics'!$C$47+I10*'Stock Statistics'!$C$48+J10*'Stock Statistics'!$C$49+K10*'Stock Statistics'!$C$50,"") -> 0.0029539728 | M10: 486.3848 | N10: 569.654 | O10: =M10/M11-1 -> 0.0064350538 | P10: =N10/N11-1 -> 0.0050446837 | Q10: =B10*'Portfolio 2 & 3'!$F$7+C10*'Portfolio 2 & 3'!$F$8+D10*'Portfolio 2 & 3'!$F$9+E10*'Portfolio 2 & 3'!$F$10+F10*'Portfolio 2 & 3'!$F$11+G10*'Portfolio 2 & 3'!$F$12+H10*'Portfolio 2 & 3'!$F$13+I10*'Portfolio 2 & 3'!$F$14+J10*'Portfolio 2 & 3'!$F$15+K10*'Portfolio 2 & 3'!$F$16 -> 0.0025484427 | R10: =B10*'Portfolio 2 & 3'!$B$23+C10*'Portfolio 2 & 3'!$B$24+D10*'Portfolio 2 & 3'!$B$25+E10*'Portfolio 2 & 3'!$B$26+F10*'Portfolio 2 & 3'!$B$27+G10*'Portfolio 2 & 3'!$B$28+H10*'Portfolio 2 & 3'!$B$29+I10*'Portfolio 2 & 3'!$B$30+J10*'Portfolio 2 & 3'!$B$31+K10*'Portfolio 2 & 3'!$B$32 -> 0.003167135 | S10: =IFERROR(AVERAGE(O10,P10),"") -> 0.0057398688
A11: 46069 | B11: -0.0064 | C11: 0.01443776 | D11: 0.034043296 | E11: 0.00099 | F11: 0.006355698 | G11: 0.044997548 | H11: 0.0010251557 | I11: 0.0017673049 | J11: 0.018700713 | K11: -0.0030801654 | L11: =IFERROR(B11*'Stock Statistics'!$C$41+C11*'Stock Statistics'!$C$42+D11*'Stock Statistics'!$C$43+E11*'Stock Statistics'!$C$44+F11*'Stock Statistics'!$C$45+G11*'Stock Statistics'!$C$46+H11*'Stock Statistics'!$C$47+I11*'Stock Statistics'!$C$48+J11*'Stock Statistics'!$C$49+K11*'Stock Statistics'!$C$50,"") -> 0.011283731 | M11: 483.2749 | N11: 566.7947 | O11: =M11/M12-1 -> 0.0049656156 | P11: =N11/N12-1 -> 0.0073962917 | Q11: =B11*'Portfolio 2 & 3'!$F$7+C11*'Portfolio 2 & 3'!$F$8+D11*'Portfolio 2 & 3'!$F$9+E11*'Portfolio 2 & 3'!$F$10+F11*'Portfolio 2 & 3'!$F$11+G11*'Portfolio 2 & 3'!$F$12+H11*'Portfolio 2 & 3'!$F$13+I11*'Portfolio 2 & 3'!$F$14+J11*'Portfolio 2 & 3'!$F$15+K11*'Portfolio 2 & 3'!$F$16 -> 0.011488836 | R11: =B11*'Portfolio 2 & 3'!$B$23+C11*'Portfolio 2 & 3'!$B$24+D11*'Portfolio 2 & 3'!$B$25+E11*'Portfolio 2 & 3'!$B$26+F11*'Portfolio 2 & 3'!$B$27+G11*'Portfolio 2 & 3'!$B$28+H11*'Portfolio 2 & 3'!$B$29+I11*'Portfolio 2 & 3'!$B$30+J11*'Portfolio 2 & 3'!$B$31+K11*'Portfolio 2 & 3'!$B$32 -> 0.008930598 | S11: =IFERROR(AVERAGE(O11,P11),"") -> 0.0061809537
A12: 46066 | B12: -0.0075 | C12: -0.079720637 | D12: -0.010622679 | E12: -0.00484 | F12: -0.017644823 | G12: 0.00019621309 | H12: -0.0053337517 | I12: -0.010146364 | J12: 0.0011278195 | K12: -0.0026677445 | L12: =IFERROR(B12*'Stock Statistics'!$C$41+C12*'Stock Statistics'!$C$42+D12*'Stock Statistics'!$C$43+E12*'Stock Statistics'!$C$44+F12*'Stock Statistics'!$C$45+G12*'Stock Statistics'!$C$46+H12*'Stock Statistics'!$C$47+I12*'Stock Statistics'!$C$48+J12*'Stock Statistics'!$C$49+K12*'Stock Statistics'!$C$50,"") -> -0.013715197 | M12: 480.887 | N12: 562.6333 | O12: =M12/M13-1 -> -0.010106899 | P12: =N12/N13-1 -> -0.0079195986 | Q12: =B12*'Portfolio 2 & 3'!$F$7+C12*'Portfolio 2 & 3'!$F$8+D12*'Portfolio 2 & 3'!$F$9+E12*'Portfolio 2 & 3'!$F$10+F12*'Portfolio 2 & 3'!$F$11+G12*'Portfolio 2 & 3'!$F$12+H12*'Portfolio 2 & 3'!$F$13+I12*'Portfolio 2 & 3'!$F$14+J12*'Portfolio 2 & 3'!$F$15+K12*'Portfolio 2 & 3'!$F$16 -> -0.013585931 | R12: =B12*'Portfolio 2 & 3'!$B$23+C12*'Portfolio 2 & 3'!$B$24+D12*'Portfolio 2 & 3'!$B$25+E12*'Portfolio 2 & 3'!$B$26+F12*'Portfolio 2 & 3'!$B$27+G12*'Portfolio 2 & 3'!$B$28+H12*'Portfolio 2 & 3'!$B$29+I12*'Portfolio 2 & 3'!$B$30+J12*'Portfolio 2 & 3'!$B$31+K12*'Portfolio 2 & 3'!$B$32 -> -0.022028215 | S12: =IFERROR(AVERAGE(O12,P12),"") -> -0.0090132486
A13: 46065 | B13: -0.0095 | C13: -0.0033106961 | D13: 0.0098552241 | E13: -0.00311 | F13: 0.025214294 | G13: 0.0050533685 | H13: 0.0036211918 | I13: 0.0022207936 | J13: -0.014741833 | K13: -0.031550928 | L13: =IFERROR(B13*'Stock Statistics'!$C$41+C13*'Stock Statistics'!$C$42+D13*'Stock Statistics'!$C$43+E13*'Stock Statistics'!$C$44+F13*'Stock Statistics'!$C$45+G13*'Stock Statistics'!$C$46+H13*'Stock Statistics'!$C$47+I13*'Stock Statistics'!$C$48+J13*'Stock Statistics'!$C$49+K13*'Stock Statistics'!$C$50,"") -> -0.0016248585 | M13: 485.7969 | N13: 567.1247 | O13: =M13/M14-1 -> -0.0032031894 | P13: =N13/N14-1 -> -0.0061762989 | Q13: =B13*'Portfolio 2 & 3'!$F$7+C13*'Portfolio 2 & 3'!$F$8+D13*'Portfolio 2 & 3'!$F$9+E13*'Portfolio 2 & 3'!$F$10+F13*'Portfolio 2 & 3'!$F$11+G13*'Portfolio 2 & 3'!$F$12+H13*'Portfolio 2 & 3'!$F$13+I13*'Portfolio 2 & 3'!$F$14+J13*'Portfolio 2 & 3'!$F$15+K13*'Portfolio 2 & 3'!$F$16 -> -0.00084215547 | R13: =B13*'Portfolio 2 & 3'!$B$23+C13*'Portfolio 2 & 3'!$B$24+D13*'Portfolio 2 & 3'!$B$25+E13*'Portfolio 2 & 3'!$B$26+F13*'Portfolio 2 & 3'!$B$27+G13*'Portfolio 2 & 3'!$B$28+H13*'Portfolio 2 & 3'!$B$29+I13*'Portfolio 2 & 3'!$B$30+J13*'Portfolio 2 & 3'!$B$31+K13*'Portfolio 2 & 3'!$B$32 -> 0.00019966471 | S13: =IFERROR(AVERAGE(O13,P13),"") -> -0.0046897441
... A1210: 44306 | B1210: 0.0078 | C1210: -0.010114729 | D1210: -0.012645161 | E1210: 0.00454 | F1210: 0.055202504 | G1210: 0.0068944904 | H1210: 0.0044256358 | I1210: -0.016219677 | J1210: 0.011611361 | K1210: -0.021759941 | L1210: =IFERROR(B1210*'Stock Statistics'!$C$41+C1210*'Stock Statistics'!$C$42+D1210*'Stock Statistics'!$C$43+E1210*'Stock Statistics'!$C$44+F1210*'Stock Statistics'!$C$45+G1210*'Stock Statistics'!$C$46+H1210*'Stock Statistics'!$C$47+I1210*'Stock Statistics'!$C$48+J1210*'Stock Statistics'!$C$49+K1210*'Stock Statistics'!$C$50,"") -> 0.0029734483 | M1210: 226.3497 | N1210: 276.3479 | O1210: =M1210/M1211-1 -> 0.017965873 | P1210: =N1210/N1211-1 -> 0.01175638 | Q1210: =B1210*'Portfolio 2 & 3'!$F$7+C1210*'Portfolio 2 & 3'!$F$8+D1210*'Portfolio 2 & 3'!$F$9+E1210*'Portfolio 2 & 3'!$F$10+F1210*'Portfolio 2 & 3'!$F$11+G1210*'Portfolio 2 & 3'!$F$12+H1210*'Portfolio 2 & 3'!$F$13+I1210*'Portfolio 2 & 3'!$F$14+J1210*'Portfolio 2 & 3'!$F$15+K1210*'Portfolio 2 & 3'!$F$16 -> 0.0035694175 | R1210: =B1210*'Portfolio 2 & 3'!$B$23+C1210*'Portfolio 2 & 3'!$B$24+D1210*'Portfolio 2 & 3'!$B$25+E1210*'Portfolio 2 & 3'!$B$26+F1210*'Portfolio 2 & 3'!$B$27+G1210*'Portfolio 2 & 3'!$B$28+H1210*'Portfolio 2 & 3'!$B$29+I1210*'Portfolio 2 & 3'!$B$30+J1210*'Portfolio 2 & 3'!$B$31+K1210*'Portfolio 2 & 3'!$B$32 -> 0.0029812182 | S1210: =IFERROR(AVERAGE(O1210,P1210),"") -> 0.014861127
A1211: 44305 | B1211: -0.016 | C1211: 0.0070003059 | D1211: -0.012336239 | E1211: 0.02344 | F1211: 9.4858661e-05 | G1211: 0.0035193665 | H1211: 0.011916195 | I1211: -0.007414207 | J1211: -0.034882443 | K1211: 0.0028677982 | L1211: =IFERROR(B1211*'Stock Statistics'!$C$41+C1211*'Stock Statistics'!$C$42+D1211*'Stock Statistics'!$C$43+E1211*'Stock Statistics'!$C$44+F1211*'Stock Statistics'!$C$45+G1211*'Stock Statistics'!$C$46+H1211*'Stock Statistics'!$C$47+I1211*'Stock Statistics'!$C$48+J1211*'Stock Statistics'!$C$49+K1211*'Stock Statistics'!$C$50,"") -> -0.0021794365 | M1211: 222.3549 | N1211: 273.1368 | O1211: =M1211/M1213-1 -> 0.0081374646 | P1211: =N1211/N1213-1 -> 0.0091200189 | Q1211: =B1211*'Portfolio 2 & 3'!$F$7+C1211*'Portfolio 2 & 3'!$F$8+D1211*'Portfolio 2 & 3'!$F$9+E1211*'Portfolio 2 & 3'!$F$10+F1211*'Portfolio 2 & 3'!$F$11+G1211*'Portfolio 2 & 3'!$F$12+H1211*'Portfolio 2 & 3'!$F$13+I1211*'Portfolio 2 & 3'!$F$14+J1211*'Portfolio 2 & 3'!$F$15+K1211*'Portfolio 2 & 3'!$F$16 -> -0.0036532386 | R1211: =B1211*'Portfolio 2 & 3'!$B$23+C1211*'Portfolio 2 & 3'!$B$24+D1211*'Portfolio 2 & 3'!$B$25+E1211*'Portfolio 2 & 3'!$B$26+F1211*'Portfolio 2 & 3'!$B$27+G1211*'Portfolio 2 & 3'!$B$28+H1211*'Portfolio 2 & 3'!$B$29+I1211*'Portfolio 2 & 3'!$B$30+J1211*'Portfolio 2 & 3'!$B$31+K1211*'Portfolio 2 & 3'!$B$32 -> -0.0029639494 | S1211: =IFERROR(AVERAGE(O1211,P1211),"") -> 0.0086287417
H1212: 0.011468049 | Q1212: =B1212*'Portfolio 2 & 3'!$F$7+C1212*'Portfolio 2 & 3'!$F$8+D1212*'Portfolio 2 & 3'!$F$9+E1212*'Portfolio 2 & 3'!$F$10+F1212*'Portfolio 2 & 3'!$F$11+G1212*'Portfolio 2 & 3'!$F$12+H1212*'Portfolio 2 & 3'!$F$13+I1212*'Portfolio 2 & 3'!$F$14+J1212*'Portfolio 2 & 3'!$F$15+K1212*'Portfolio 2 & 3'!$F$16 -> 0.0018765898 | R1212: =B1212*'Portfolio 2 & 3'!$B$23+C1212*'Portfolio 2 & 3'!$B$24+D1212*'Portfolio 2 & 3'!$B$25+E1212*'Portfolio 2 & 3'!$B$26+F1212*'Portfolio 2 & 3'!$B$27+G1212*'Portfolio 2 & 3'!$B$28+H1212*'Portfolio 2 & 3'!$B$29+I1212*'Portfolio 2 & 3'!$B$30+J1212*'Portfolio 2 & 3'!$B$31+K1212*'Portfolio 2 & 3'!$B$32 -> 0.00034404147
A1213: 44302 | B1213: 0.003 | C1213: -0.0067563944 | D1213: 0.014112903 | E1213: -0.00425 | F1213: 0.044382802 | G1213: -0.00073931983 | H1213: -0.0025310198 | I1213: 0.014179318 | J1213: -0.00016477179 | K1213: 0.038738382 | L1213: =IFERROR(B1213*'Stock Statistics'!$C$41+C1213*'Stock Statistics'!$C$42+D1213*'Stock Statistics'!$C$43+E1213*'Stock Statistics'!$C$44+F1213*'Stock Statistics'!$C$45+G1213*'Stock Statistics'!$C$46+H1213*'Stock Statistics'!$C$47+I1213*'Stock Statistics'!$C$48+J1213*'Stock Statistics'!$C$49+K1213*'Stock Statistics'!$C$50,"") -> 0.0099971899 | M1213: 220.5601 | N1213: 270.6683 | O1213: =M1213/M1214-1 -> -0.0072198884 | Q1213: =B1213*'Portfolio 2 & 3'!$F$7+C1213*'Portfolio 2 & 3'!$F$8+D1213*'Portfolio 2 & 3'!$F$9+E1213*'Portfolio 2 & 3'!$F$10+F1213*'Portfolio 2 & 3'!$F$11+G1213*'Portfolio 2 & 3'!$F$12+H1213*'Portfolio 2 & 3'!$F$13+I1213*'Portfolio 2 & 3'!$F$14+J1213*'Portfolio 2 & 3'!$F$15+K1213*'Portfolio 2 & 3'!$F$16 -> 0.0094669859 | R1213: =B1213*'Portfolio 2 & 3'!$B$23+C1213*'Portfolio 2 & 3'!$B$24+D1213*'Portfolio 2 & 3'!$B$25+E1213*'Portfolio 2 & 3'!$B$26+F1213*'Portfolio 2 & 3'!$B$27+G1213*'Portfolio 2 & 3'!$B$28+H1213*'Portfolio 2 & 3'!$B$29+I1213*'Portfolio 2 & 3'!$B$30+J1213*'Portfolio 2 & 3'!$B$31+K1213*'Portfolio 2 & 3'!$B$32 -> 0.012996334 | S1213: =IFERROR(AVERAGE(O1213,P1213),"") -> -0.0072198884
A1214: 44301 | B1214: -0.0027 | C1214: 0.020688523 | D1214: 0.0043613707 | E1214: -0.01425 | F1214: 0.030105113 | G1214: -0.008911597 | H1214: -0.0018651193 | I1214: 0.02759585 | J1214: 0.0042471042 | K1214: 0.0072760521 | L1214: =IFERROR(B1214*'Stock Statistics'!$C$41+C1214*'Stock Statistics'!$C$42+D1214*'Stock Statistics'!$C$43+E1214*'Stock Statistics'!$C$44+F1214*'Stock Statistics'!$C$45+G1214*'Stock Statistics'!$C$46+H1214*'Stock Statistics'!$C$47+I1214*'Stock Statistics'!$C$48+J1214*'Stock Statistics'!$C$49+K1214*'Stock Statistics'!$C$50,"") -> 0.0066547296 | M1214: 222.1641 | O1214: =M1214/M1215-1 -> -0.0081029918 | Q1214: =B1214*'Portfolio 2 & 3'!$F$7+C1214*'Portfolio 2 & 3'!$F$8+D1214*'Portfolio 2 & 3'!$F$9+E1214*'Portfolio 2 & 3'!$F$10+F1214*'Portfolio 2 & 3'!$F$11+G1214*'Portfolio 2 & 3'!$F$12+H1214*'Portfolio 2 & 3'!$F$13+I1214*'Portfolio 2 & 3'!$F$14+J1214*'Portfolio 2 & 3'!$F$15+K1214*'Portfolio 2 & 3'!$F$16 -> 0.007214254 | R1214: =B1214*'Portfolio 2 & 3'!$B$23+C1214*'Portfolio 2 & 3'!$B$24+D1214*'Portfolio 2 & 3'!$B$25+E1214*'Portfolio 2 & 3'!$B$26+F1214*'Portfolio 2 & 3'!$B$27+G1214*'Portfolio 2 & 3'!$B$28+H1214*'Portfolio 2 & 3'!$B$29+I1214*'Portfolio 2 & 3'!$B$30+J1214*'Portfolio 2 & 3'!$B$31+K1214*'Portfolio 2 & 3'!$B$32 -> 0.015057383 | S1214: =IFERROR(AVERAGE(O1214,P1214),"") -> -0.0081029918
A1215: 44299 | B1215: -0.006 | C1215: -0.0030737332 | D1215: -0.0098704503 | E1215: -0.00136 | F1215: -0.019511707 | G1215: 0.0053156543 | H1215: 0 | I1215: 7.3594348e-05 | J1215: -0.0040650407 | K1215: -0.0067409407 | L1215: =IFERROR(B1215*'Stock Statistics'!$C$41+C1215*'Stock Statistics'!$C$42+D1215*'Stock Statistics'!$C$43+E1215*'Stock Statistics'!$C$44+F1215*'Stock Statistics'!$C$45+G1215*'Stock Statistics'!$C$46+H1215*'Stock Statistics'!$C$47+I1215*'Stock Statistics'!$C$48+J1215*'Stock Statistics'!$C$49+K1215*'Stock Statistics'!$C$50,"") -> -0.0045232623 | M1215: 223.979 | O1215: =M1215/M1216-1 -> 0.021622105 | Q1215: =B1215*'Portfolio 2 & 3'!$F$7+C1215*'Portfolio 2 & 3'!$F$8+D1215*'Portfolio 2 & 3'!$F$9+E1215*'Portfolio 2 & 3'!$F$10+F1215*'Portfolio 2 & 3'!$F$11+G1215*'Portfolio 2 & 3'!$F$12+H1215*'Portfolio 2 & 3'!$F$13+I1215*'Portfolio 2 & 3'!$F$14+J1215*'Portfolio 2 & 3'!$F$15+K1215*'Portfolio 2 & 3'!$F$16 -> -0.0049495191 | R1215: =B1215*'Portfolio 2 & 3'!$B$23+C1215*'Portfolio 2 & 3'!$B$24+D1215*'Portfolio 2 & 3'!$B$25+E1215*'Portfolio 2 & 3'!$B$26+F1215*'Portfolio 2 & 3'!$B$27+G1215*'Portfolio 2 & 3'!$B$28+H1215*'Portfolio 2 & 3'!$B$29+I1215*'Portfolio 2 & 3'!$B$30+J1215*'Portfolio 2 & 3'!$B$31+K1215*'Portfolio 2 & 3'!$B$32 -> -0.0047197531 | S1215: =IFERROR(AVERAGE(O1215,P1215),"") -> 0.021622105
A1216: 44298 | B1216: -0.0121 | C1216: -0.014941952 | D1216: 0.0014415157 | E1216: -0.01154 | F1216: -0.028671397 | G1216: -0.0080965264 | H1216: -0.025606508 | I1216: -0.0058530875 | J1216: -0.0024112231 | K1216: 0.032925073 | L1216: =IFERROR(B1216*'Stock Statistics'!$C$41+C1216*'Stock Statistics'!$C$42+D1216*'Stock Statistics'!$C$43+E1216*'Stock Statistics'!$C$44+F1216*'Stock Statistics'!$C$45+G1216*'Stock Statistics'!$C$46+H1216*'Stock Statistics'!$C$47+I1216*'Stock Statistics'!$C$48+J1216*'Stock Statistics'!$C$49+K1216*'Stock Statistics'!$C$50,"") -> -0.0074854105 | M1216: 219.2386 | O1216: =M1216/M1217-1 -> 0.0031200142 | Q1216: =B1216*'Portfolio 2 & 3'!$F$7+C1216*'Portfolio 2 & 3'!$F$8+D1216*'Portfolio 2 & 3'!$F$9+E1216*'Portfolio 2 & 3'!$F$10+F1216*'Portfolio 2 & 3'!$F$11+G1216*'Portfolio 2 & 3'!$F$12+H1216*'Portfolio 2 & 3'!$F$13+I1216*'Portfolio 2 & 3'!$F$14+J1216*'Portfolio 2 & 3'!$F$15+K1216*'Portfolio 2 & 3'!$F$16 -> -0.0087417134 | R1216: =B1216*'Portfolio 2 & 3'!$B$23+C1216*'Portfolio 2 & 3'!$B$24+D1216*'Portfolio 2 & 3'!$B$25+E1216*'Portfolio 2 & 3'!$B$26+F1216*'Portfolio 2 & 3'!$B$27+G1216*'Portfolio 2 & 3'!$B$28+H1216*'Portfolio 2 & 3'!$B$29+I1216*'Portfolio 2 & 3'!$B$30+J1216*'Portfolio 2 & 3'!$B$31+K1216*'Portfolio 2 & 3'!$B$32 -> -0.0093218694 | S1216: =IFERROR(AVERAGE(O1216,P1216),"") -> 0.0031200142
A1217: 44295 | B1217: 0.0181 | C1217: 0.014670327 | D1217: -0.022298284 | E1217: 0.02892 | F1217: 0.092946675 | G1217: -0.017367175 | H1217: 0.0083579774 | I1217: 0.059288538 | J1217: 0.0077313894 | K1217: 0.0012170117 | L1217: =IFERROR(B1217*'Stock Statistics'!$C$41+C1217*'Stock Statistics'!$C$42+D1217*'Stock Statistics'!$C$43+E1217*'Stock Statistics'!$C$44+F1217*'Stock Statistics'!$C$45+G1217*'Stock Statistics'!$C$46+H1217*'Stock Statistics'!$C$47+I1217*'Stock Statistics'!$C$48+J1217*'Stock Statistics'!$C$49+K1217*'Stock Statistics'!$C$50,"") -> 0.019156646 | M1217: 218.5567 | O1217: =M1217/M1218-1 -> 0.007487586 | Q1217: =B1217*'Portfolio 2 & 3'!$F$7+C1217*'Portfolio 2 & 3'!$F$8+D1217*'Portfolio 2 & 3'!$F$9+E1217*'Portfolio 2 & 3'!$F$10+F1217*'Portfolio 2 & 3'!$F$11+G1217*'Portfolio 2 & 3'!$F$12+H1217*'Portfolio 2 & 3'!$F$13+I1217*'Portfolio 2 & 3'!$F$14+J1217*'Portfolio 2 & 3'!$F$15+K1217*'Portfolio 2 & 3'!$F$16 -> 0.018007099 | R1217: =B1217*'Portfolio 2 & 3'!$B$23+C1217*'Portfolio 2 & 3'!$B$24+D1217*'Portfolio 2 & 3'!$B$25+E1217*'Portfolio 2 & 3'!$B$26+F1217*'Portfolio 2 & 3'!$B$27+G1217*'Portfolio 2 & 3'!$B$28+H1217*'Portfolio 2 & 3'!$B$29+I1217*'Portfolio 2 & 3'!$B$30+J1217*'Portfolio 2 & 3'!$B$31+K1217*'Portfolio 2 & 3'!$B$32 -> 0.033195322 | S1217: =IFERROR(AVERAGE(O1217,P1217),"") -> 0.007487586
A1218: 44294 | B1218: -0.0229 | C1218: -0.00047242664 | D1218: 0.00015102698 | E1218: -0.03568 | F1218: 0.019493177 | G1218: -0.010806764 | H1218: 0.037972263 | I1218: -0.021313714 | J1218: -0.032278752 | K1218: 0.0065241995 | L1218: =IFERROR(B1218*'Stock Statistics'!$C$41+C1218*'Stock Statistics'!$C$42+D1218*'Stock Statistics'!$C$43+E1218*'Stock Statistics'!$C$44+F1218*'Stock Statistics'!$C$45+G1218*'Stock Statistics'!$C$46+H1218*'Stock Statistics'!$C$47+I1218*'Stock Statistics'!$C$48+J1218*'Stock Statistics'!$C$49+K1218*'Stock Statistics'!$C$50,"") -> -0.0059310989 | M1218: 216.9324 | O1218: =M1218/M1219-1 -> 0.010954331 | Q1218: =B1218*'Portfolio 2 & 3'!$F$7+C1218*'Portfolio 2 & 3'!$F$8+D1218*'Portfolio 2 & 3'!$F$9+E1218*'Portfolio 2 & 3'!$F$10+F1218*'Portfolio 2 & 3'!$F$11+G1218*'Portfolio 2 & 3'!$F$12+H1218*'Portfolio 2 & 3'!$F$13+I1218*'Portfolio 2 & 3'!$F$14+J1218*'Portfolio 2 & 3'!$F$15+K1218*'Portfolio 2 & 3'!$F$16 -> -0.0025041784 | R1218: =B1218*'Portfolio 2 & 3'!$B$23+C1218*'Portfolio 2 & 3'!$B$24+D1218*'Portfolio 2 & 3'!$B$25+E1218*'Portfolio 2 & 3'!$B$26+F1218*'Portfolio 2 & 3'!$B$27+G1218*'Portfolio 2 & 3'!$B$28+H1218*'Portfolio 2 & 3'!$B$29+I1218*'Portfolio 2 & 3'!$B$30+J1218*'Portfolio 2 & 3'!$B$31+K1218*'Portfolio 2 & 3'!$B$32 -> -0.0059168822 | S1218: =IFERROR(AVERAGE(O1218,P1218),"") -> 0.010954331
A1219: 44293 | B1219: 0.0065 | C1219: 0.0022581996 | D1219: 0.0059758939 | E1219: 0.01283 | F1219: 0.011391019 | G1219: 0.0033317926 | H1219: 0.015296582 | I1219: 0.0072580029 | J1219: -0.0092656324 | K1219: -0.0064687674 | L1219: =IFERROR(B1219*'Stock Statistics'!$C$41+C1219*'Stock Statistics'!$C$42+D1219*'Stock Statistics'!$C$43+E1219*'Stock Statistics'!$C$44+F1219*'Stock Statistics'!$C$45+G1219*'Stock Statistics'!$C$46+H1219*'Stock Statistics'!$C$47+I1219*'Stock Statistics'!$C$48+J1219*'Stock Statistics'!$C$49+K1219*'Stock Statistics'!$C$50,"") -> 0.004910709 | M1219: 214.5818 | O1219: =M1219/M1220-1 -> -0.0036338411 | Q1219: =B1219*'Portfolio 2 & 3'!$F$7+C1219*'Portfolio 2 & 3'!$F$8+D1219*'Portfolio 2 & 3'!$F$9+E1219*'Portfolio 2 & 3'!$F$10+F1219*'Portfolio 2 & 3'!$F$11+G1219*'Portfolio 2 & 3'!$F$12+H1219*'Portfolio 2 & 3'!$F$13+I1219*'Portfolio 2 & 3'!$F$14+J1219*'Portfolio 2 & 3'!$F$15+K1219*'Portfolio 2 & 3'!$F$16 -> 0.0049990601 | R1219: =B1219*'Portfolio 2 & 3'!$B$23+C1219*'Portfolio 2 & 3'!$B$24+D1219*'Portfolio 2 & 3'!$B$25+E1219*'Portfolio 2 & 3'!$B$26+F1219*'Portfolio 2 & 3'!$B$27+G1219*'Portfolio 2 & 3'!$B$28+H1219*'Portfolio 2 & 3'!$B$29+I1219*'Portfolio 2 & 3'!$B$30+J1219*'Portfolio 2 & 3'!$B$31+K1219*'Portfolio 2 & 3'!$B$32 -> 0.0049386606 | S1219: =IFERROR(AVERAGE(O1219,P1219),"") -> -0.0036338411
A1220: 44292 | B1220: 0.0037 | C1220: -0.030628818 | D1220: 0.022155503 | E1220: 0.0188 | F1220: 0.037617911 | G1220: -0.0088948273 | H1220: 0.015296582 | I1220: 0.015438324 | J1220: -0.0052143685 | K1220: -0.0071970791 | L1220: =IFERROR(B1220*'Stock Statistics'!$C$41+C1220*'Stock Statistics'!$C$42+D1220*'Stock Statistics'!$C$43+E1220*'Stock Statistics'!$C$44+F1220*'Stock Statistics'!$C$45+G1220*'Stock Statistics'!$C$46+H1220*'Stock Statistics'!$C$47+I1220*'Stock Statistics'!$C$48+J1220*'Stock Statistics'!$C$49+K1220*'Stock Statistics'!$C$50,"") -> 0.0061073228 | M1220: 215.3644 | Q1220: =B1220*'Portfolio 2 & 3'!$F$7+C1220*'Portfolio 2 & 3'!$F$8+D1220*'Portfolio 2 & 3'!$F$9+E1220*'Portfolio 2 & 3'!$F$10+F1220*'Portfolio 2 & 3'!$F$11+G1220*'Portfolio 2 & 3'!$F$12+H1220*'Portfolio 2 & 3'!$F$13+I1220*'Portfolio 2 & 3'!$F$14+J1220*'Portfolio 2 & 3'!$F$15+K1220*'Portfolio 2 & 3'!$F$16 -> 0.0074760509 | R1220: =B1220*'Portfolio 2 & 3'!$B$23+C1220*'Portfolio 2 & 3'!$B$24+D1220*'Portfolio 2 & 3'!$B$25+E1220*'Portfolio 2 & 3'!$B$26+F1220*'Portfolio 2 & 3'!$B$27+G1220*'Portfolio 2 & 3'!$B$28+H1220*'Portfolio 2 & 3'!$B$29+I1220*'Portfolio 2 & 3'!$B$30+J1220*'Portfolio 2 & 3'!$B$31+K1220*'Portfolio 2 & 3'!$B$32 -> 0.003429969
A1221: 44291 | B1221: 0.012 | C1221: 0.046500028 | D1221: 0.013536201 | E1221: 0.00176 | F1221: -0.0041874151 | G1221: 0.021247563 | H1221: 0.0098440837 | I1221: 0.0017096674 | J1221: 0.003170242 | K1221: -0.0038593875 | L1221: =IFERROR(B1221*'Stock Statistics'!$C$41+C1221*'Stock Statistics'!$C$42+D1221*'Stock Statistics'!$C$43+E1221*'Stock Statistics'!$C$44+F1221*'Stock Statistics'!$C$45+G1221*'Stock Statistics'!$C$46+H1221*'Stock Statistics'!$C$47+I1221*'Stock Statistics'!$C$48+J1221*'Stock Statistics'!$C$49+K1221*'Stock Statistics'!$C$50,"") -> 0.010172098 | M1221: 215.3644 | Q1221: =B1221*'Portfolio 2 & 3'!$F$7+C1221*'Portfolio 2 & 3'!$F$8+D1221*'Portfolio 2 & 3'!$F$9+E1221*'Portfolio 2 & 3'!$F$10+F1221*'Portfolio 2 & 3'!$F$11+G1221*'Portfolio 2 & 3'!$F$12+H1221*'Portfolio 2 & 3'!$F$13+I1221*'Portfolio 2 & 3'!$F$14+J1221*'Portfolio 2 & 3'!$F$15+K1221*'Portfolio 2 & 3'!$F$16 -> 0.0098824137 | R1221: =B1221*'Portfolio 2 & 3'!$B$23+C1221*'Portfolio 2 & 3'!$B$24+D1221*'Portfolio 2 & 3'!$B$25+E1221*'Portfolio 2 & 3'!$B$26+F1221*'Portfolio 2 & 3'!$B$27+G1221*'Portfolio 2 & 3'!$B$28+H1221*'Portfolio 2 & 3'!$B$29+I1221*'Portfolio 2 & 3'!$B$30+J1221*'Portfolio 2 & 3'!$B$31+K1221*'Portfolio 2 & 3'!$B$32 -> 0.012755909
A1222: 44287 | B1222: - | C1222: -0.0075539502 | D1222: 0.041245561 | E1222: 0.02921 | F1222: - | G1222: -0.00064286132 | H1222: 0.014286312 | I1222: 0.0064919828 | J1222: 0.0087948404 | K1222: 0.010162817 | M1222: 215.3644

Sheet Stock Statistics
A1: Statistic | B1: ABBOTINDIA | C1: ALKEM | D1: AUROPHARMA | E1: LUPIN | F1: ZYDUSLIFE | G1: TORNTPHARM | H1: DRREDDY | I1: SUNPHARMA | J1: CIPLA | K1: DIVISLAB | L1: Portfolio | N1: Beta according to SBI
A2: Average daily return | B2: =AVERAGE(Return!B2:B1222) -> 0.00057563577 | C2: =AVERAGE(Return!C2:C1222) -> 0.00070174899 | D2: =AVERAGE(Return!D2:D1222) -> 0.00041206038 | E2: =AVERAGE(Return!E2:E1222) -> -0.00083860656 | F2: =AVERAGE(Return!F2:F1222) -> 0.00073313558 | G2: =AVERAGE(Return!G2:G1222) -> 0.00069980424 | H2: =AVERAGE(Return!H2:H1222) -> 0.00034703912 | I2: =AVERAGE(Return!I2:I1222) -> 0.00090240985 | ... L2: =AVERAGE(Return!L2:L1222) -> 0.00044181682 | N2: ABBOTINDIA | O2: ALKEM | P2: AUROPHARMA | Q2: LUPIN | R2: ZYDUSLIFE | S2: TORNTPHARM | T2: DRREDDY | U2: SUNPHARMA | V2: CIPLA | W2: DIVISLAB | X2: Portfolio
A3: Annualised Return | B3: =(1+B2)^250-1 -> 0.15473114 | C3: =(1+C2)^250-1 -> 0.19169388 | D3: =(1+D2)^250-1 -> 0.10848462 | E3: =(1+E2)^250-1 -> -0.18920465 | F3: =(1+F2)^250-1 -> 0.2010747 | G3: =(1+G2)^250-1 -> 0.19111504 | H3: =(1+H2)^250-1 -> 0.090618241 | I3: =(1+I2)^250-1 -> 0.25294995 | ... L3: =(1+L2)^250-1 -> 0.11675796 | N3: =SLOPE(Return!B2:B1211,Return!$O2:$O1211) -> 0.045935988 | O3: =SLOPE(Return!C2:C1211,Return!$O2:$O1211) -> 0.22438762 | P3: =SLOPE(Return!D2:D1211,Return!$O2:$O1211) -> 0.2777692 | Q3: =SLOPE(Return!E2:E1211,Return!$O2:$O1211) -> 0.25092372 | R3: =SLOPE(Return!F2:F1211,Return!$O2:$O1211) -> 0.11041863 | S3: =SLOPE(Return!G2:G1211,Return!$O2:$O1211) -> 0.10610691 | T3: =SLOPE(Return!H2:H1211,Return!$O2:$O1211) -> 0.2112045 | U3: =SLOPE(Return!I2:I1211,Return!$O2:$O1211) -> 0.18545173 | ... X3: =SLOPE(Return!L2:L1211,Return!$O2:$O1211) -> 0.19945766
A4: Std Dev | B4: =_xlfn.STDEV.S(Return!B2:B1222) -> 0.014732172 | C4: =_xlfn.STDEV.S(Return!C2:C1222) -> 0.014563005 | D4: =_xlfn.STDEV.S(Return!D2:D1222) -> 0.018773751 | E4: =_xlfn.STDEV.S(Return!E2:E1222) -> 0.016286497 | F4: =_xlfn.STDEV.S(Return!F2:F1222) -> 0.016137311 | G4: =_xlfn.STDEV.S(Return!G2:G1222) -> 0.020651316 | H4: =_xlfn.STDEV.S(Return!H2:H1222) -> 0.013477545 | I4: =_xlfn.STDEV.S(Return!I2:I1222) -> 0.012903922 | ... L4: =_xlfn.STDEV.S(Return!L2:L1222) -> 0.0064362724
A5: Annualised Std Dev | B5: =B4*SQRT(250) -> 0.2329361 | C5: =C4*SQRT(250) -> 0.23026133 | D5: =D4*SQRT(250) -> 0.29683907 | E5: =E4*SQRT(250) -> 0.25751213 | F5: =F4*SQRT(250) -> 0.25515329 | G5: =G4*SQRT(250) -> 0.32652598 | H5: =H4*SQRT(250) -> 0.21309869 | I5: =I4*SQRT(250) -> 0.20402893 | ... L5: =L4*SQRT(250) -> 0.1017664 | N5: Beta according to Nippon
N6: ABBOTINDIA | O6: ALKEM | P6: AUROPHARMA | Q6: LUPIN | R6: ZYDUSLIFE | S6: TORNTPHARM | T6: DRREDDY | U6: SUNPHARMA | V6: CIPLA | W6: DIVISLAB | X6: Portfolio
N7: =SLOPE(Return!B2:B1211,Return!$P2:$P1211) -> -0.026022458 | O7: =SLOPE(Return!C2:C1211,Return!$P2:$P1211) -> 0.014063207 | P7: =SLOPE(Return!D2:D1211,Return!$P2:$P1211) -> -0.030827369 | Q7: =SLOPE(Return!E2:E1211,Return!$P2:$P1211) -> -0.033248149 | R7: =SLOPE(Return!F2:F1211,Return!$P2:$P1211) -> 0.024797469 | S7: =SLOPE(Return!G2:G1211,Return!$P2:$P1211) -> 0.17293478 | T7: =SLOPE(Return!H2:H1211,Return!$P2:$P1211) -> 0.025535619 | U7: =SLOPE(Return!I2:I1211,Return!$P2:$P1211) -> 0.050417095 | ... X7: =SLOPE(Return!L2:L1211,Return!$P2:$P1211) -> 0.01641682
B8: Covariance
C10: ALKEM | D10: AUROPHARMA | E10: LUPIN | F10: ZYDUSLIFE | G10: TORNTPHARM | H10: DRREDDY | I10: SUNPHARMA | J10: CIPLA | K10: DIVISLAB | V10: *Dr Reddy stock was split in 1:5
B11: ABBOTINDIA | C11: =_xlfn.COVARIANCE.S(Return!$B$2:$B$1222,Return!C$2:C$1222) -> 4.031475e-06 | D11: =_xlfn.COVARIANCE.S(Return!$B$2:$B$1222,Return!D$2:D$1222) -> -9.7300499e-07 | E11: =_xlfn.COVARIANCE.S(Return!$B$2:$B$1222,Return!E$2:E$1222) -> 2.9718721e-06 | F11: =_xlfn.COVARIANCE.S(Return!$B$2:$B$1222,Return!F$2:F$1222) -> 6.2970134e-05 | G11: =_xlfn.COVARIANCE.S(Return!$B$2:$B$1222,Return!G$2:G$1222) -> -4.731463e-06 | H11: =_xlfn.COVARIANCE.S(Return!$B$2:$B$1222,Return!H$2:H$1222) -> 7.1374483e-06 | I11: =_xlfn.COVARIANCE.S(Return!$B$2:$B$1222,Return!I$2:I$1222) -> 1.6086347e-06 | J11: =_xlfn.COVARIANCE.S(Return!$B$2:$B$1222,Return!J$2:J$1222) -> -9.7495095e-06 | K11: =_xlfn.COVARIANCE.S(Return!$B$2:$B$1222,Return!K$2:K$1222) -> 8.1942435e-06 | P11: ABBOTINDIA | Q11: ALKEM | R11: AUROPHARMA | S11: LUPIN | T11: ZYDUSLIFE | U11: TORNTPHARM | V11: DRREDDY | W11: SUNPHARMA | X11: CIPLA | Y11: DIVISLAB | Z11: SBI MF | AA11: Nippon MF
B12: ALKEM | D12: =_xlfn.COVARIANCE.S(Return!$C$2:$C$1222,Return!D$2:D$1222) -> 2.0172359e-05 | E12: =_xlfn.COVARIANCE.S(Return!$C$2:$C$1222,Return!E$2:E$1222) -> -4.5822191e-08 | F12: =_xlfn.COVARIANCE.S(Return!$C$2:$C$1222,Return!F$2:F$1222) -> 2.1280782e-05 | G12: =_xlfn.COVARIANCE.S(Return!$C$2:$C$1222,Return!G$2:G$1222) -> 1.2751614e-05 | H12: =_xlfn.COVARIANCE.S(Return!$C$2:$C$1222,Return!H$2:H$1222) -> 9.4844112e-06 | I12: =_xlfn.COVARIANCE.S(Return!$C$2:$C$1222,Return!I$2:I$1222) -> 1.9998704e-05 | J12: =_xlfn.COVARIANCE.S(Return!$C$2:$C$1222,Return!J$2:J$1222) -> 1.4373805e-05 | K12: =_xlfn.COVARIANCE.S(Return!$C$2:$C$1222,Return!K$2:K$1222) -> 2.6776763e-05 | N12: Start date | O12: =Return!A1211 -> 44305 | P12: 14724.8 | Q12: 2745.55 | R12: 987.3 | S12: 1064.65 | T12: 456.5 | U12: 2596.2 | V12: 4968.11 | W12: 654.45 | X12: 944.35 | Y12: 3779.7 | Z12: =Return!M1211 -> 222.3549 | AA12: =Return!N1211 -> 273.1368
B13: AUROPHARMA | E13: =_xlfn.COVARIANCE.S(Return!$D$2:$D$1222,Return!E$2:E$1222) -> 5.1450215e-05 | F13: =_xlfn.COVARIANCE.S(Return!$D$2:$D$1222,Return!F$2:F$1222) -> 1.1415962e-05 | G13: =_xlfn.COVARIANCE.S(Return!$D$2:$D$1222,Return!G$2:G$1222) -> 3.7897018e-05 | H13: =_xlfn.COVARIANCE.S(Return!$D$2:$D$1222,Return!H$2:H$1222) -> 4.7726193e-05 | I13: =_xlfn.COVARIANCE.S(Return!$D$2:$D$1222,Return!I$2:I$1222) -> 1.4668746e-05 | J13: =_xlfn.COVARIANCE.S(Return!$D$2:$D$1222,Return!J$2:J$1222) -> 1.2523297e-05 | K13: =_xlfn.COVARIANCE.S(Return!$D$2:$D$1222,Return!K$2:K$1222) -> 3.2801129e-05 | N13: End Date | O13: =Return!A2 -> 46080 | P13: 26530 | Q13: 5639.5 | R13: 1220.4 | S13: 2301.9 | T13: 921.7 | U13: 4333.3 | V13: 6431.5 | W13: 1737 | X13: 1348.2 | Y13: 6408.5 | Z13: =Return!M2 -> 497.1341 | AA13: =Return!N2 -> 576.9248
B14: LUPIN | F14: =_xlfn.COVARIANCE.S(Return!$E$2:$E$1222,Return!F$2:F$1222) -> 1.4631847e-05 | G14: =_xlfn.COVARIANCE.S(Return!$E$2:$E$1222,Return!G2:G1222) -> 5.5595583e-05 | H14: =_xlfn.COVARIANCE.S(Return!$E$2:$E$1222,Return!H2:H1222) -> 6.8511272e-05 | I14: =_xlfn.COVARIANCE.S(Return!$E$2:$E$1222,Return!I2:I1222) -> 5.6225766e-06 | J14: =_xlfn.COVARIANCE.S(Return!$E$2:$E$1222,Return!J2:J1222) -> 7.112167e-06 | K14: =_xlfn.COVARIANCE.S(Return!$E$2:$E$1222,Return!K2:K1222) -> 1.2826064e-05 | N14: Time | O14: =YEARFRAC(O12,O13,1) -> 4.8607942
B15: ZYDUSLIFE | G15: =_xlfn.COVARIANCE.S(Return!$F$2:$F$1222,Return!G$2:G$1222) -> 1.1332858e-05 | H15: =_xlfn.COVARIANCE.S(Return!$F$2:$F$1222,Return!H$2:H$1222) -> 8.2637962e-06 | I15: =_xlfn.COVARIANCE.S(Return!$F$2:$F$1222,Return!I$2:I$1222) -> 9.0745388e-06 | J15: =_xlfn.COVARIANCE.S(Return!$F$2:$F$1222,Return!J$2:J$1222) -> -6.9361765e-07 | K15: =_xlfn.COVARIANCE.S(Return!$F$2:$F$1222,Return!K$2:K$1222) -> 2.7814913e-08 | N15: Actual Return | P15: =(P13/P12)^(1/$O$14)-1 -> 0.1287612 | Q15: =(Q13/Q12)^(1/$O$14)-1 -> 0.15961224 | R15: =(R13/R12)^(1/$O$14)-1 -> 0.04457076 | S15: =(S13/S12)^(1/$O$14)-1 -> 0.17190932 | T15: =(T13/T12)^(1/$O$14)-1 -> 0.15552025 | U15: =(U13/U12)^(1/$O$14)-1 -> 0.1111442 | V15: =(V13/V12)^(1/$O$14)-1 -> 0.05454814 | W15: =(W13/W12)^(1/$O$14)-1 -> 0.22239841 | ... Y15: =(Y13/Y12)^(1/$O$14)-1 -> 0.11473893
B16: TORNTPHARM | H16: =_xlfn.COVARIANCE.S(Return!$G$2:$G$1222,Return!H$2:H$1222) -> 3.0445859e-05 | I16: =_xlfn.COVARIANCE.S(Return!$G$2:$G$1222,Return!I$2:I$1222) -> 1.4711128e-05 | J16: =_xlfn.COVARIANCE.S(Return!$G$2:$G$1222,Return!J$2:J$1222) -> 8.1431e-06 | K16: =_xlfn.COVARIANCE.S(Return!$G$2:$G$1222,Return!K$2:K$1222) -> -5.445339e-06 | N16: Expected Return | O16: SBI | P16: =$P$18+N3*(P19-$P$18) -> 0.073336239 | Q16: =$P$18+O3*(Q19-$P$18) -> 0.093289447 | R16: =$P$18+P3*(R19-$P$18) -> 0.0992582 | S16: =$P$18+Q3*(S19-$P$18) -> 0.096256527 | T16: =$P$18+R3*(T19-$P$18) -> 0.080546235 | U16: =$P$18+S3*(U19-$P$18) -> 0.080064129 | V16: =$P$18+T3*(V19-$P$18) -> 0.091815403 | W16: =$P$18+U3*(W19-$P$18) -> 0.088935909 | ... Y16: =$P$18+W3*(Y19-$P$18) -> 0.10910196
B17: DRREDDY | I17: =_xlfn.COVARIANCE.S(Return!$H$2:$H$1222,Return!I$2:I$1222) -> 1.8442668e-06 | J17: =_xlfn.COVARIANCE.S(Return!$H$2:$H$1222,Return!J$2:J$1222) -> 1.1254041e-05 | K17: =_xlfn.COVARIANCE.S(Return!$H$2:$H$1222,Return!K$2:K$1222) -> 1.3179578e-05 | O17: Nippon | P17: =$P$18+N7*(P20-$P$18) -> 0.065647369 | Q17: =$P$18+O7*(Q20-$P$18) -> 0.069579507 | R17: =$P$18+P7*(R20-$P$18) -> 0.06517604 | S17: =$P$18+Q7*(S20-$P$18) -> 0.064938577 | T17: =$P$18+R7*(T20-$P$18) -> 0.070632467 | U17: =$P$18+S7*(U20-$P$18) -> 0.085163754 | V17: =$P$18+T7*(V20-$P$18) -> 0.070704875 | W17: =$P$18+U7*(W20-$P$18) -> 0.073145583 | ... Y17: =$P$18+W7*(Y20-$P$18) -> 0.061485914
B18: SUNPHARMA | J18: =_xlfn.COVARIANCE.S(Return!$I$2:$I$1222,Return!J$2:J$1222) -> 2.4152633e-05 | K18: =_xlfn.COVARIANCE.S(Return!$I$2:$I$1222,Return!K$2:K$1222) -> 2.7605554e-05 | N18: Rf | P18: 0.0682 | Q18: 0.0682 | R18: 0.0682 | S18: 0.0682 | T18: 0.0682 | U18: 0.0682 | V18: 0.0682 | W18: 0.0682 | X18: 0.0682 | Y18: 0.0682
B19: CIPLA | K19: =_xlfn.COVARIANCE.S(Return!$J$2:$J$1222,Return!K$2:K$1222) -> 6.3869456e-05 | N19: Rm | O19: SBI | P19: =RATE($O$14,0,-$Z$12,$Z$13,0) -> 0.18001297 | Q19: =RATE($O$14,0,-$Z$12,$Z$13,0) -> 0.18001297 | R19: =RATE($O$14,0,-$Z$12,$Z$13,0) -> 0.18001297 | S19: =RATE($O$14,0,-$Z$12,$Z$13,0) -> 0.18001297 | T19: =RATE($O$14,0,-$Z$12,$Z$13,0) -> 0.18001297 | U19: =RATE($O$14,0,-$Z$12,$Z$13,0) -> 0.18001297 | V19: =RATE($O$14,0,-$Z$12,$Z$13,0) -> 0.18001297 | W19: =RATE($O$14,0,-$Z$12,$Z$13,0) -> 0.18001297 | ... Y19: =RATE($O$14,0,-$Z$12,$Z$13,0) -> 0.18001297
B20: DIVISLAB | O20: Nippon | P20: =RATE($O$14,0,-$AA$12,$AA$13,0) -> 0.16629337 | Q20: =RATE($O$14,0,-$AA$12,$AA$13,0) -> 0.16629337 | R20: =RATE($O$14,0,-$AA$12,$AA$13,0) -> 0.16629337 | S20: =RATE($O$14,0,-$AA$12,$AA$13,0) -> 0.16629337 | T20: =RATE($O$14,0,-$AA$12,$AA$13,0) -> 0.16629337 | U20: =RATE($O$14,0,-$AA$12,$AA$13,0) -> 0.16629337 | V20: =RATE($O$14,0,-$AA$12,$AA$13,0) -> 0.16629337 | W20: =RATE($O$14,0,-$AA$12,$AA$13,0) -> 0.16629337 | ... Y20: =RATE($O$14,0,-$AA$12,$AA$13,0) -> 0.16629337
N21: Jenson Alpha | P21: =(P15-P16)/100 -> 0.0005542496 | Q21: =(Q15-Q16)/100 -> 0.00066322796 | R21: =(R15-R16)/100 -> -0.0005468744 | S21: =(S15-S16)/100 -> 0.00075652794 | T21: =(T15-T16)/100 -> 0.00074974018 | U21: =(U15-U16)/100 -> 0.00031080073 | V21: =(V15-V16)/100 -> -0.00037267263 | W21: =(W15-W16)/100 -> 0.001334625 | ... Y21: =(Y15-Y16)/100 -> 5.6369729e-05
B23: Correlation | N23: Sharp Ratio of portfolio | O23: =(L3-P18)/L5 -> 0.47715121
N24: Treynor Ratio | O24: SBI | P24: Nippon
C25: ALKEM | D25: AUROPHARMA | E25: LUPIN | F25: ZYDUSLIFE | G25: TORNTPHARM | H25: DRREDDY | I25: SUNPHARMA | J25: CIPLA | K25: DIVISLAB | O25: =(L3-P18)/X3 -> 0.24344997 | P25: =(L3-Q18)/X7 -> 2.9578179
B26: ABBOTINDIA | C26: =CORREL(Return!$B$2:$B$1222,Return!C$2:C$1222) -> 0.018785609 | D26: =CORREL(Return!$B$2:$B$1222,Return!D$2:D$1222) -> -0.0035234172 | E26: =CORREL(Return!$B$2:$B$1222,Return!E$2:E$1222) -> 0.012398386 | F26: =CORREL(Return!$B$2:$B$1222,Return!F$2:F$1222) -> 0.26487237 | G26: =CORREL(Return!$B$2:$B$1222,Return!G$2:G$1222) -> -0.015545456 | H26: =CORREL(Return!$B$2:$B$1222,Return!H$2:H$1222) -> 0.03594359 | I26: =CORREL(Return!$B$2:$B$1222,Return!I$2:I$1222) -> 0.0084590994 | J26: =CORREL(Return!$B$2:$B$1222,Return!J$2:J$1222) -> -0.04587704 | K26: =CORREL(Return!$B$2:$B$1222,Return!K$2:K$1222) -> 0.032977363
B27: ALKEM | D27: =CORREL(Return!$C$2:$C$1222,Return!D$2:D$1222) -> 0.073782716 | E27: =CORREL(Return!$C$2:$C$1222,Return!E$2:E$1222) -> -0.00019319557 | F27: =CORREL(Return!$C$2:$C$1222,Return!F$2:F$1222) -> 0.09052833 | G27: =CORREL(Return!$C$2:$C$1222,Return!G$2:G$1222) -> 0.042400057 | H27: =CORREL(Return!$C$2:$C$1222,Return!H$2:H$1222) -> 0.048316099 | I27: =CORREL(Return!$C$2:$C$1222,Return!I$2:I$1222) -> 0.10642144 | J27: =CORREL(Return!$C$2:$C$1222,Return!J$2:J$1222) -> 0.068441255 | K27: =CORREL(Return!$C$2:$C$1222,Return!K$2:K$1222) -> 0.10904393
B28: AUROPHARMA | E28: =CORREL(Return!$D$2:$D$1222,Return!E$2:E$1222) -> 0.16827068 | F28: =CORREL(Return!$D$2:$D$1222,Return!F$2:F$1222) -> 0.037739588 | G28: =CORREL(Return!$D$2:$D$1222,Return!G$2:G$1222) -> 0.097747635 | H28: =CORREL(Return!$D$2:$D$1222,Return!H$2:H$1222) -> 0.1885985 | I28: =CORREL(Return!$D$2:$D$1222,Return!I$2:I$1222) -> 0.060550842 | J28: =CORREL(Return!$D$2:$D$1222,Return!J$2:J$1222) -> 0.046255655 | K28: =CORREL(Return!$D$2:$D$1222,Return!K$2:K$1222) -> 0.10361727
B29: LUPIN | F29: =CORREL(Return!$E$2:$E$1222,Return!F$2:F$1222) -> 0.055727533 | G29: =CORREL(Return!$E$2:$E$1222,Return!G$2:G$1222) -> 0.16529696 | H29: =CORREL(Return!$E$2:$E$1222,Return!H$2:H$1222) -> 0.31208064 | I29: =CORREL(Return!$E$2:$E$1222,Return!I$2:I$1222) -> 0.026753829 | J29: =CORREL(Return!$E$2:$E$1222,Return!J$2:J$1222) -> 0.030281088 | K29: =CORREL(Return!$E$2:$E$1222,Return!K$2:K$1222) -> 0.046704651
B30: ZYDUSLIFE | G30: =CORREL(Return!$F$2:$F$1222,Return!G$2:G$1222) -> 0.033992499 | H30: =CORREL(Return!$F$2:$F$1222,Return!H$2:H$1222) -> 0.037992135 | I30: =CORREL(Return!$F$2:$F$1222,Return!I$2:I$1222) -> 0.043563915 | J30: =CORREL(Return!$F$2:$F$1222,Return!J$2:J$1222) -> -0.0029796715 | K30: =CORREL(Return!$F$2:$F$1222,Return!K$2:K$1222) -> 0.00010219282
B31: TORNTPHARM | H31: =CORREL(Return!$G$2:$G$1222,Return!H$2:H$1222) -> 0.10937372 | I31: =CORREL(Return!$G$2:$G$1222,Return!I$2:I$1222) -> 0.055204756 | J31: =CORREL(Return!$G$2:$G$1222,Return!J$2:J$1222) -> 0.027342565 | K31: =CORREL(Return!$G$2:$G$1222,Return!K$2:K$1222) -> -0.015637654
B32: DRREDDY | I32: =CORREL(Return!$H$2:$H$1222,Return!I$2:I$1222) -> 0.01060314 | J32: =CORREL(Return!$H$2:$H$1222,Return!J$2:J$1222) -> 0.057894619 | K32: =CORREL(Return!$H$2:$H$1222,Return!K$2:K$1222) -> 0.057986702
B33: SUNPHARMA | J33: =CORREL(Return!$I$2:$I$1222,Return!J$2:J$1222) -> 0.12978962 | K33: =CORREL(Return!$I$2:$I$1222,Return!K$2:K$1222) -> 0.12687298
B34: CIPLA | K34: =CORREL(Return!$J$2:$J$1222,Return!K$2:K$1222) -> 0.26265449
B35: DIVISLAB
B39: A | C39: B
B40: Stock | C40: Weight
B41: ABBOTINDIA | C41: 0.1
B42: ALKEM | C42: 0.1
B43: AUROPHARMA | C43: 0.1
B44: LUPIN | C44: 0.1
B45: ZYDUSLIFE | C45: 0.1
...

Sheet Dashboard_Data
A1: Portfolio | B1: Return | C1: StdDev | D1: Beta | E1: Sharpe | F1: Treynor | G1: Alpha
A2: Portfolio 1 - Equal Weight | B2: ='Stock Statistics'!L3 -> 0.11675796 | C2: ='Stock Statistics'!L5 -> 0.1017664 | D2: ='Stock Statistics'!X3 -> 0.19945766 | E2: ='Stock Statistics'!O23 -> 0.47715121 | F2: ='Stock Statistics'!O25 -> 0.24344997 | G2: ='Stock Statistics'!L3-('Stock Statistics'!P18+'Stock Statistics'!X3*('Stock Statistics'!P19-'Stock Statistics'!P18)) -> 0.026256008
A3: Portfolio 2 - Fundamentals | B3: ='Portfolio 2 & 3'!J8 -> 0.11758308 | C3: ='Portfolio 2 & 3'!J10 -> 0.10414616 | D3: ='Portfolio 2 & 3'!J11 -> 0.20342873 | E3: ='Portfolio 2 & 3'!J15 -> 0.47417095 | F3: ='Portfolio 2 & 3'!J16 -> 0.24275372 | G3: ='Portfolio 2 & 3'!J14 -> 0.02663711
A4: Portfolio 3 - Markowitz | B4: ='Portfolio 2 & 3'!E24 -> 0.19368659 | C4: ='Portfolio 2 & 3'!E26 -> 0.11037186 | D4: ='Portfolio 2 & 3'!E27 -> 0.16794586 | E4: ='Portfolio 2 & 3'!E31 -> 1.1369437 | F4: ='Portfolio 2 & 3'!E32 -> 0.74718478 | G4: ='Portfolio 2 & 3'!E30 -> 0.10670806
